<?xml version="1.0"?>
<robot name="jackal_robot" xmlns:xacro="http://ros.org/wiki/xacro">

    <!-- Include Sensor Definitions -->
    <xacro:include filename="$(find barn_navigation)/urdf/sensors.urdf.xacro" />
	<xacro:imu_sensor parent="base_link"/>
	<xacro:lidar_sensor parent="base_link"/>
	<xacro:camera_sensor parent="base_link"/>
	<xacro:additional_sensor parent="base_link"/>

    <!-- Main Robot Description -->
    <link name="base_link">
        <visual>
            <geometry>
                <box size="0.5 0.4 0.2"/>  <!-- Approximate chassis size -->
            </geometry>
            <material name="blue">
                <color rgba="0.0 0.0 1.0 1.0"/>
            </material>
        </visual>
        <collision>
            <geometry>
                <box size="0.5 0.4 0.2"/>
            </geometry>
        </collision>
        <inertial>
            <mass value="20.0"/>  <!-- Approximate Jackal weight -->
            <origin xyz="0 0 0"/>
            <inertia ixx="0.1" ixy="0.0" ixz="0.0" iyy="0.1" iyz="0.0" izz="0.1"/>
        </inertial>
    </link>

    <!-- Wheels -->
    <joint name="wheel_front_left_joint" type="continuous">
        <parent link="base_link"/>
        <child link="wheel_front_left"/>
        <origin xyz="0.2 0.15 0"/>
        <axis xyz="0 1 0"/>
    </joint>
    
    <link name="wheel_front_left">
        <visual>
            <geometry>
                <cylinder length="0.05" radius="0.08"/>
            </geometry>
            <material name="black"/>
        </visual>
    </link>

    <joint name="wheel_front_right_joint" type="continuous">
        <parent link="base_link"/>
        <child link="wheel_front_right"/>
        <origin xyz="0.2 -0.15 0"/>
        <axis xyz="0 1 0"/>
    </joint>
    
    <link name="wheel_front_right">
        <visual>
            <geometry>
                <cylinder length="0.05" radius="0.08"/>
            </geometry>
            <material name="black"/>
        </visual>
    </link>

    <joint name="wheel_rear_left_joint" type="continuous">
        <parent link="base_link"/>
        <child link="wheel_rear_left"/>
        <origin xyz="-0.2 0.15 0"/>
        <axis xyz="0 1 0"/>
    </joint>

    <link name="wheel_rear_left">
        <visual>
            <geometry>
                <cylinder length="0.05" radius="0.08"/>
            </geometry>
            <material name="black"/>
        </visual>
    </link>

    <joint name="wheel_rear_right_joint" type="continuous">
        <parent link="base_link"/>
        <child link="wheel_rear_right"/>
        <origin xyz="-0.2 -0.15 0"/>
        <axis xyz="0 1 0"/>
    </joint>

    <link name="wheel_rear_right">
        <visual>
            <geometry>
                <cylinder length="0.05" radius="0.08"/>
            </geometry>
            <material name="black"/>
        </visual>
    </link>

    <!-- Load Sensors 
    <xacro:imu_sensor parent="base_link"/>
    <xacro:lidar_sensor parent="base_link"/>
    <xacro:camera_sensor parent="base_link"/>
    <xacro:additional_sensor parent="base_link"/> -->

    <!-- Transmission for Differential Drive -->
    <transmission name="diff_drive">
        <type>transmission_interface/SimpleTransmission</type>
        <joint name="wheel_front_left_joint">
            <hardwareInterface>EffortJointInterface</hardwareInterface>
        </joint>
        <joint name="wheel_front_right_joint">
            <hardwareInterface>EffortJointInterface</hardwareInterface>
        </joint>
    </transmission>

</robot>